<?xml version='1.0'?>
<sdf version='1.6'>
  <model name='rkek'>
    <link name='link_0'>
      <inertial>
        <mass>1</mass>
        <inertia>
          <ixx>0.166667</ixx>
          <ixy>0</ixy>
          <ixz>0</ixz>
          <iyy>0.166667</iyy>
          <iyz>0</iyz>
          <izz>0.166667</izz>
        </inertia>
        <pose frame=''>0 0 0 0 -0 0</pose>
      </inertial>
      <pose frame=''>-0.021663 -0.042612 0.085714 0 -0 0</pose>
      <gravity>1</gravity>
      <self_collide>0</self_collide>
      <kinematic>0</kinematic>
      <enable_wind>0</enable_wind>
      <visual name='visual'>
        <pose frame=''>0 0 0 0 -0 0</pose>
        <geometry>
          <box>
            <size>0.6 0.3 0.1</size>
          </box>
        </geometry>
        <material>
          <lighting>1</lighting>
          <script>
            <uri>file://media/materials/scripts/gazebo.material</uri>
            <name>Gazebo/Grey</name>
          </script>
          <shader type='vertex'>
            <normal_map>__default__</normal_map>
          </shader>
          <ambient>1 0 0 1</ambient>
          <diffuse>0.7 0.7 0.7 1</diffuse>
          <specular>0.01 0.01 0.01 1</specular>
          <emissive>0 0 0 1</emissive>
        </material>
        <transparency>0</transparency>
        <cast_shadows>1</cast_shadows>
      </visual>
      <collision name='collision'>
        <laser_retro>0</laser_retro>
        <max_contacts>10</max_contacts>
        <pose frame=''>0 0 0 0 -0 0</pose>
        <geometry>
          <box>
            <size>0.6 0.3 0.1</size>
          </box>
        </geometry>
        <surface>
          <friction>
            <ode>
              <mu>1</mu>
              <mu2>1</mu2>
              <fdir1>0 0 0</fdir1>
              <slip1>0</slip1>
              <slip2>0</slip2>
            </ode>
            <torsional>
              <coefficient>1</coefficient>
              <patch_radius>0</patch_radius>
              <surface_radius>0</surface_radius>
              <use_patch_radius>1</use_patch_radius>
              <ode>
                <slip>0</slip>
              </ode>
            </torsional>
          </friction>
          <bounce>
            <restitution_coefficient>0</restitution_coefficient>
            <threshold>1e+06</threshold>
          </bounce>
          <contact>
            <collide_without_contact>0</collide_without_contact>
            <collide_without_contact_bitmask>1</collide_without_contact_bitmask>
            <collide_bitmask>1</collide_bitmask>
            <ode>
              <soft_cfm>0</soft_cfm>
              <soft_erp>0.2</soft_erp>
              <kp>1e+13</kp>
              <kd>1</kd>
              <max_vel>0.01</max_vel>
              <min_depth>0</min_depth>
            </ode>
            <bullet>
              <split_impulse>1</split_impulse>
              <split_impulse_penetration_threshold>-0.01</split_impulse_penetration_threshold>
              <soft_cfm>0</soft_cfm>
              <soft_erp>0.2</soft_erp>
              <kp>1e+13</kp>
              <kd>1</kd>
            </bullet>
          </contact>
        </surface>
      </collision>
    </link>
    <link name='link_2'>
      <inertial>
        <mass>1</mass>
        <inertia>
          <ixx>0.166667</ixx>
          <ixy>0</ixy>
          <ixz>0</ixz>
          <iyy>0.166667</iyy>
          <iyz>0</iyz>
          <izz>0.166667</izz>
        </inertia>
        <pose frame=''>0 0 0 0 -0 0</pose>
      </inertial>
      <pose frame=''>0.128337 -0.19434 -0.014286 0.000572 1.5707 -1.57013</pose>
      <gravity>1</gravity>
      <self_collide>0</self_collide>
      <kinematic>0</kinematic>
      <enable_wind>0</enable_wind>
      <visual name='visual'>
        <pose frame=''>0 0 0 0 -0 0</pose>
        <geometry>
          <polyline>
            <height>0.1</height>
            <point>-0.0999998 0.049686</point>
            <point>-0.0977624 0.0286855</point>
            <point>-0.0912994 0.00893357</point>
            <point>-0.080955 -0.00897376</point>
            <point>-0.0670737 -0.0244405</point>
            <point>-0.0499998 -0.0368705</point>
            <point>-0.0306891 -0.0454448</point>
            <point>-0.0103446 -0.049732</point>
            <point>0.0103446 -0.049732</point>
            <point>0.0306891 -0.0454448</point>
            <point>0.0499998 -0.0368705</point>
            <point>0.0670808 -0.0244341</point>
            <point>0.0809659 -0.00895876</point>
            <point>0.0913106 0.00895864</point>
            <point>0.0977701 0.0287212</point>
            <point>0.0999998 0.049732</point>
            <point>0.0899999 0.049732</point>
            <point>0.0879932 0.0308222</point>
            <point>0.0821797 0.0130359</point>
            <point>0.0728696 -0.00308987</point>
            <point>0.060373 -0.0170178</point>
            <point>0.0450001 -0.0282106</point>
            <point>0.0276204 -0.0359275</point>
            <point>0.00931019 -0.039786</point>
            <point>-0.00931018 -0.039786</point>
            <point>-0.0276204 -0.0359275</point>
            <point>-0.0450001 -0.0282106</point>
            <point>-0.060373 -0.0170178</point>
            <point>-0.0728696 -0.00308987</point>
            <point>-0.0821797 0.0130359</point>
            <point>-0.0879932 0.0308222</point>
            <point>-0.0899999 0.0497319</point>
            <point>-0.0999998 0.049732</point>
          </polyline>
        </geometry>
        <material>
          <lighting>1</lighting>
          <script>
            <uri>file://media/materials/scripts/gazebo.material</uri>
            <name>Gazebo/Grey</name>
          </script>
          <shader type='vertex'>
            <normal_map>__default__</normal_map>
          </shader>
          <ambient>1 1 1 1</ambient>
          <diffuse>0.7 0.7 0.7 1</diffuse>
          <specular>0.01 0.01 0.01 1</specular>
          <emissive>0 0 0 1</emissive>
        </material>
        <transparency>0</transparency>
        <cast_shadows>1</cast_shadows>
      </visual>
      <collision name='collision'>
        <laser_retro>0</laser_retro>
        <max_contacts>10</max_contacts>
        <pose frame=''>0 0 0 0 -0 0</pose>
        <geometry>
          <polyline>
            <height>0.1</height>
            <point>-0.0999998 0.049686</point>
            <point>-0.0977624 0.0286855</point>
            <point>-0.0912994 0.00893357</point>
            <point>-0.080955 -0.00897376</point>
            <point>-0.0670737 -0.0244405</point>
            <point>-0.0499998 -0.0368705</point>
            <point>-0.0306891 -0.0454448</point>
            <point>-0.0103446 -0.049732</point>
            <point>0.0103446 -0.049732</point>
            <point>0.0306891 -0.0454448</point>
            <point>0.0499998 -0.0368705</point>
            <point>0.0670808 -0.0244341</point>
            <point>0.0809659 -0.00895876</point>
            <point>0.0913106 0.00895864</point>
            <point>0.0977701 0.0287212</point>
            <point>0.0999998 0.049732</point>
            <point>0.0899999 0.049732</point>
            <point>0.0879932 0.0308222</point>
            <point>0.0821797 0.0130359</point>
            <point>0.0728696 -0.00308987</point>
            <point>0.060373 -0.0170178</point>
            <point>0.0450001 -0.0282106</point>
            <point>0.0276204 -0.0359275</point>
            <point>0.00931019 -0.039786</point>
            <point>-0.00931018 -0.039786</point>
            <point>-0.0276204 -0.0359275</point>
            <point>-0.0450001 -0.0282106</point>
            <point>-0.060373 -0.0170178</point>
            <point>-0.0728696 -0.00308987</point>
            <point>-0.0821797 0.0130359</point>
            <point>-0.0879932 0.0308222</point>
            <point>-0.0899999 0.0497319</point>
            <point>-0.0999998 0.049732</point>
          </polyline>
        </geometry>
        <surface>
          <friction>
            <ode>
              <mu>1</mu>
              <mu2>1</mu2>
              <fdir1>0 0 0</fdir1>
              <slip1>0</slip1>
              <slip2>0</slip2>
            </ode>
            <torsional>
              <coefficient>1</coefficient>
              <patch_radius>0</patch_radius>
              <surface_radius>0</surface_radius>
              <use_patch_radius>1</use_patch_radius>
              <ode>
                <slip>0</slip>
              </ode>
            </torsional>
          </friction>
          <bounce>
            <restitution_coefficient>0</restitution_coefficient>
            <threshold>1e+06</threshold>
          </bounce>
          <contact>
            <collide_without_contact>0</collide_without_contact>
            <collide_without_contact_bitmask>1</collide_without_contact_bitmask>
            <collide_bitmask>1</collide_bitmask>
            <ode>
              <soft_cfm>0</soft_cfm>
              <soft_erp>0.2</soft_erp>
              <kp>1e+13</kp>
              <kd>1</kd>
              <max_vel>0.01</max_vel>
              <min_depth>0</min_depth>
            </ode>
            <bullet>
              <split_impulse>1</split_impulse>
              <split_impulse_penetration_threshold>-0.01</split_impulse_penetration_threshold>
              <soft_cfm>0</soft_cfm>
              <soft_erp>0.2</soft_erp>
              <kp>1e+13</kp>
              <kd>1</kd>
            </bullet>
          </contact>
        </surface>
      </collision>
    </link>
    <link name='link_2_clone'>
      <inertial>
        <mass>1</mass>
        <inertia>
          <ixx>0.166667</ixx>
          <ixy>0</ixy>
          <ixz>0</ixz>
          <iyy>0.166667</iyy>
          <iyz>0</iyz>
          <izz>0.166667</izz>
        </inertia>
        <pose frame=''>0 0 0 0 -0 0</pose>
      </inertial>
      <pose frame=''>-0.071663 -0.312626 -0.014286 0.000572 1.5707 -1.57013</pose>
      <gravity>1</gravity>
      <self_collide>0</self_collide>
      <kinematic>0</kinematic>
      <enable_wind>0</enable_wind>
      <visual name='visual'>
        <pose frame=''>0 0 0 0 -0 0</pose>
        <geometry>
          <polyline>
            <height>0.1</height>
            <point>-0.0999998 0.049686</point>
            <point>-0.0977624 0.0286855</point>
            <point>-0.0912994 0.00893357</point>
            <point>-0.080955 -0.00897376</point>
            <point>-0.0670737 -0.0244405</point>
            <point>-0.0499998 -0.0368705</point>
            <point>-0.0306891 -0.0454448</point>
            <point>-0.0103446 -0.049732</point>
            <point>0.0103446 -0.049732</point>
            <point>0.0306891 -0.0454448</point>
            <point>0.0499998 -0.0368705</point>
            <point>0.0670808 -0.0244341</point>
            <point>0.0809659 -0.00895876</point>
            <point>0.0913106 0.00895864</point>
            <point>0.0977701 0.0287212</point>
            <point>0.0999998 0.049732</point>
            <point>0.0899999 0.049732</point>
            <point>0.0879932 0.0308222</point>
            <point>0.0821797 0.0130359</point>
            <point>0.0728696 -0.00308987</point>
            <point>0.060373 -0.0170178</point>
            <point>0.0450001 -0.0282106</point>
            <point>0.0276204 -0.0359275</point>
            <point>0.00931019 -0.039786</point>
            <point>-0.00931018 -0.039786</point>
            <point>-0.0276204 -0.0359275</point>
            <point>-0.0450001 -0.0282106</point>
            <point>-0.060373 -0.0170178</point>
            <point>-0.0728696 -0.00308987</point>
            <point>-0.0821797 0.0130359</point>
            <point>-0.0879932 0.0308222</point>
            <point>-0.0899999 0.0497319</point>
            <point>-0.0999998 0.049732</point>
          </polyline>
        </geometry>
        <material>
          <lighting>1</lighting>
          <script>
            <uri>file://media/materials/scripts/gazebo.material</uri>
            <name>Gazebo/Grey</name>
          </script>
          <shader type='vertex'>
            <normal_map>__default__</normal_map>
          </shader>
          <ambient>1 1 1 1</ambient>
          <diffuse>0.7 0.7 0.7 1</diffuse>
          <specular>0.01 0.01 0.01 1</specular>
          <emissive>0 0 0 1</emissive>
        </material>
        <transparency>0</transparency>
        <cast_shadows>1</cast_shadows>
      </visual>
      <collision name='collision'>
        <laser_retro>0</laser_retro>
        <max_contacts>10</max_contacts>
        <pose frame=''>0 0 0 0 -0 0</pose>
        <geometry>
          <polyline>
            <height>0.1</height>
            <point>-0.0999998 0.049686</point>
            <point>-0.0977624 0.0286855</point>
            <point>-0.0912994 0.00893357</point>
            <point>-0.080955 -0.00897376</point>
            <point>-0.0670737 -0.0244405</point>
            <point>-0.0499998 -0.0368705</point>
            <point>-0.0306891 -0.0454448</point>
            <point>-0.0103446 -0.049732</point>
            <point>0.0103446 -0.049732</point>
            <point>0.0306891 -0.0454448</point>
            <point>0.0499998 -0.0368705</point>
            <point>0.0670808 -0.0244341</point>
            <point>0.0809659 -0.00895876</point>
            <point>0.0913106 0.00895864</point>
            <point>0.0977701 0.0287212</point>
            <point>0.0999998 0.049732</point>
            <point>0.0899999 0.049732</point>
            <point>0.0879932 0.0308222</point>
            <point>0.0821797 0.0130359</point>
            <point>0.0728696 -0.00308987</point>
            <point>0.060373 -0.0170178</point>
            <point>0.0450001 -0.0282106</point>
            <point>0.0276204 -0.0359275</point>
            <point>0.00931019 -0.039786</point>
            <point>-0.00931018 -0.039786</point>
            <point>-0.0276204 -0.0359275</point>
            <point>-0.0450001 -0.0282106</point>
            <point>-0.060373 -0.0170178</point>
            <point>-0.0728696 -0.00308987</point>
            <point>-0.0821797 0.0130359</point>
            <point>-0.0879932 0.0308222</point>
            <point>-0.0899999 0.0497319</point>
            <point>-0.0999998 0.049732</point>
          </polyline>
        </geometry>
        <surface>
          <friction>
            <ode>
              <mu>1</mu>
              <mu2>1</mu2>
              <fdir1>0 0 0</fdir1>
              <slip1>0</slip1>
              <slip2>0</slip2>
            </ode>
            <torsional>
              <coefficient>1</coefficient>
              <patch_radius>0</patch_radius>
              <surface_radius>0</surface_radius>
              <use_patch_radius>1</use_patch_radius>
              <ode>
                <slip>0</slip>
              </ode>
            </torsional>
          </friction>
          <bounce>
            <restitution_coefficient>0</restitution_coefficient>
            <threshold>1e+06</threshold>
          </bounce>
          <contact>
            <collide_without_contact>0</collide_without_contact>
            <collide_without_contact_bitmask>1</collide_without_contact_bitmask>
            <collide_bitmask>1</collide_bitmask>
            <ode>
              <soft_cfm>0</soft_cfm>
              <soft_erp>0.2</soft_erp>
              <kp>1e+13</kp>
              <kd>1</kd>
              <max_vel>0.01</max_vel>
              <min_depth>0</min_depth>
            </ode>
            <bullet>
              <split_impulse>1</split_impulse>
              <split_impulse_penetration_threshold>-0.01</split_impulse_penetration_threshold>
              <soft_cfm>0</soft_cfm>
              <soft_erp>0.2</soft_erp>
              <kp>1e+13</kp>
              <kd>1</kd>
            </bullet>
          </contact>
        </surface>
      </collision>
    </link>
    <link name='link_2_clone_0'>
      <inertial>
        <mass>1</mass>
        <inertia>
          <ixx>0.166667</ixx>
          <ixy>0</ixy>
          <ixz>0</ixz>
          <iyy>0.166667</iyy>
          <iyz>0</iyz>
          <izz>0.166667</izz>
        </inertia>
        <pose frame=''>0 0 0 0 -0 0</pose>
      </inertial>
      <pose frame=''>-0.271663 -0.192626 -0.014286 0.000572 1.5707 -1.57013</pose>
      <gravity>1</gravity>
      <self_collide>0</self_collide>
      <kinematic>0</kinematic>
      <enable_wind>0</enable_wind>
      <visual name='visual'>
        <pose frame=''>0 0 0 0 -0 0</pose>
        <geometry>
          <polyline>
            <height>0.1</height>
            <point>-0.0999998 0.049686</point>
            <point>-0.0977624 0.0286855</point>
            <point>-0.0912994 0.00893357</point>
            <point>-0.080955 -0.00897376</point>
            <point>-0.0670737 -0.0244405</point>
            <point>-0.0499998 -0.0368705</point>
            <point>-0.0306891 -0.0454448</point>
            <point>-0.0103446 -0.049732</point>
            <point>0.0103446 -0.049732</point>
            <point>0.0306891 -0.0454448</point>
            <point>0.0499998 -0.0368705</point>
            <point>0.0670808 -0.0244341</point>
            <point>0.0809659 -0.00895876</point>
            <point>0.0913106 0.00895864</point>
            <point>0.0977701 0.0287212</point>
            <point>0.0999998 0.049732</point>
            <point>0.0899999 0.049732</point>
            <point>0.0879932 0.0308222</point>
            <point>0.0821797 0.0130359</point>
            <point>0.0728696 -0.00308987</point>
            <point>0.060373 -0.0170178</point>
            <point>0.0450001 -0.0282106</point>
            <point>0.0276204 -0.0359275</point>
            <point>0.00931019 -0.039786</point>
            <point>-0.00931018 -0.039786</point>
            <point>-0.0276204 -0.0359275</point>
            <point>-0.0450001 -0.0282106</point>
            <point>-0.060373 -0.0170178</point>
            <point>-0.0728696 -0.00308987</point>
            <point>-0.0821797 0.0130359</point>
            <point>-0.0879932 0.0308222</point>
            <point>-0.0899999 0.0497319</point>
            <point>-0.0999998 0.049732</point>
          </polyline>
        </geometry>
        <material>
          <lighting>1</lighting>
          <script>
            <uri>file://media/materials/scripts/gazebo.material</uri>
            <name>Gazebo/Grey</name>
          </script>
          <shader type='vertex'>
            <normal_map>__default__</normal_map>
          </shader>
          <ambient>1 1 1 1</ambient>
          <diffuse>0.7 0.7 0.7 1</diffuse>
          <specular>0.01 0.01 0.01 1</specular>
          <emissive>0 0 0 1</emissive>
        </material>
        <transparency>0</transparency>
        <cast_shadows>1</cast_shadows>
      </visual>
      <collision name='collision'>
        <laser_retro>0</laser_retro>
        <max_contacts>10</max_contacts>
        <pose frame=''>0 0 0 0 -0 0</pose>
        <geometry>
          <polyline>
            <height>0.1</height>
            <point>-0.0999998 0.049686</point>
            <point>-0.0977624 0.0286855</point>
            <point>-0.0912994 0.00893357</point>
            <point>-0.080955 -0.00897376</point>
            <point>-0.0670737 -0.0244405</point>
            <point>-0.0499998 -0.0368705</point>
            <point>-0.0306891 -0.0454448</point>
            <point>-0.0103446 -0.049732</point>
            <point>0.0103446 -0.049732</point>
            <point>0.0306891 -0.0454448</point>
            <point>0.0499998 -0.0368705</point>
            <point>0.0670808 -0.0244341</point>
            <point>0.0809659 -0.00895876</point>
            <point>0.0913106 0.00895864</point>
            <point>0.0977701 0.0287212</point>
            <point>0.0999998 0.049732</point>
            <point>0.0899999 0.049732</point>
            <point>0.0879932 0.0308222</point>
            <point>0.0821797 0.0130359</point>
            <point>0.0728696 -0.00308987</point>
            <point>0.060373 -0.0170178</point>
            <point>0.0450001 -0.0282106</point>
            <point>0.0276204 -0.0359275</point>
            <point>0.00931019 -0.039786</point>
            <point>-0.00931018 -0.039786</point>
            <point>-0.0276204 -0.0359275</point>
            <point>-0.0450001 -0.0282106</point>
            <point>-0.060373 -0.0170178</point>
            <point>-0.0728696 -0.00308987</point>
            <point>-0.0821797 0.0130359</point>
            <point>-0.0879932 0.0308222</point>
            <point>-0.0899999 0.0497319</point>
            <point>-0.0999998 0.049732</point>
          </polyline>
        </geometry>
        <surface>
          <friction>
            <ode>
              <mu>1</mu>
              <mu2>1</mu2>
              <fdir1>0 0 0</fdir1>
              <slip1>0</slip1>
              <slip2>0</slip2>
            </ode>
            <torsional>
              <coefficient>1</coefficient>
              <patch_radius>0</patch_radius>
              <surface_radius>0</surface_radius>
              <use_patch_radius>1</use_patch_radius>
              <ode>
                <slip>0</slip>
              </ode>
            </torsional>
          </friction>
          <bounce>
            <restitution_coefficient>0</restitution_coefficient>
            <threshold>1e+06</threshold>
          </bounce>
          <contact>
            <collide_without_contact>0</collide_without_contact>
            <collide_without_contact_bitmask>1</collide_without_contact_bitmask>
            <collide_bitmask>1</collide_bitmask>
            <ode>
              <soft_cfm>0</soft_cfm>
              <soft_erp>0.2</soft_erp>
              <kp>1e+13</kp>
              <kd>1</kd>
              <max_vel>0.01</max_vel>
              <min_depth>0</min_depth>
            </ode>
            <bullet>
              <split_impulse>1</split_impulse>
              <split_impulse_penetration_threshold>-0.01</split_impulse_penetration_threshold>
              <soft_cfm>0</soft_cfm>
              <soft_erp>0.2</soft_erp>
              <kp>1e+13</kp>
              <kd>1</kd>
            </bullet>
          </contact>
        </surface>
      </collision>
    </link>
    <link name='link_2_clone_1'>
      <inertial>
        <mass>1</mass>
        <inertia>
          <ixx>0.166667</ixx>
          <ixy>0</ixy>
          <ixz>0</ixz>
          <iyy>0.166667</iyy>
          <iyz>0</iyz>
          <izz>0.166667</izz>
        </inertia>
        <pose frame=''>0 0 0 0 -0 0</pose>
      </inertial>
      <pose frame=''>-0.271663 0.207402 -0.014286 0.000592 1.5707 -1.57015</pose>
      <gravity>1</gravity>
      <self_collide>0</self_collide>
      <kinematic>0</kinematic>
      <enable_wind>0</enable_wind>
      <visual name='visual'>
        <pose frame=''>0 0 0 0 -0 0</pose>
        <geometry>
          <polyline>
            <height>0.1</height>
            <point>-0.0999998 0.049686</point>
            <point>-0.0977624 0.0286855</point>
            <point>-0.0912994 0.00893357</point>
            <point>-0.080955 -0.00897376</point>
            <point>-0.0670737 -0.0244405</point>
            <point>-0.0499998 -0.0368705</point>
            <point>-0.0306891 -0.0454448</point>
            <point>-0.0103446 -0.049732</point>
            <point>0.0103446 -0.049732</point>
            <point>0.0306891 -0.0454448</point>
            <point>0.0499998 -0.0368705</point>
            <point>0.0670808 -0.0244341</point>
            <point>0.0809659 -0.00895876</point>
            <point>0.0913106 0.00895864</point>
            <point>0.0977701 0.0287212</point>
            <point>0.0999998 0.049732</point>
            <point>0.0899999 0.049732</point>
            <point>0.0879932 0.0308222</point>
            <point>0.0821797 0.0130359</point>
            <point>0.0728696 -0.00308987</point>
            <point>0.060373 -0.0170178</point>
            <point>0.0450001 -0.0282106</point>
            <point>0.0276204 -0.0359275</point>
            <point>0.00931019 -0.039786</point>
            <point>-0.00931018 -0.039786</point>
            <point>-0.0276204 -0.0359275</point>
            <point>-0.0450001 -0.0282106</point>
            <point>-0.060373 -0.0170178</point>
            <point>-0.0728696 -0.00308987</point>
            <point>-0.0821797 0.0130359</point>
            <point>-0.0879932 0.0308222</point>
            <point>-0.0899999 0.0497319</point>
            <point>-0.0999998 0.049732</point>
          </polyline>
        </geometry>
        <material>
          <lighting>1</lighting>
          <script>
            <uri>file://media/materials/scripts/gazebo.material</uri>
            <name>Gazebo/Grey</name>
          </script>
          <shader type='vertex'>
            <normal_map>__default__</normal_map>
          </shader>
          <ambient>1 1 1 1</ambient>
          <diffuse>0.7 0.7 0.7 1</diffuse>
          <specular>0.01 0.01 0.01 1</specular>
          <emissive>0 0 0 1</emissive>
        </material>
        <transparency>0</transparency>
        <cast_shadows>1</cast_shadows>
      </visual>
      <collision name='collision'>
        <laser_retro>0</laser_retro>
        <max_contacts>10</max_contacts>
        <pose frame=''>0 0 0 0 -0 0</pose>
        <geometry>
          <polyline>
            <height>0.1</height>
            <point>-0.0999998 0.049686</point>
            <point>-0.0977624 0.0286855</point>
            <point>-0.0912994 0.00893357</point>
            <point>-0.080955 -0.00897376</point>
            <point>-0.0670737 -0.0244405</point>
            <point>-0.0499998 -0.0368705</point>
            <point>-0.0306891 -0.0454448</point>
            <point>-0.0103446 -0.049732</point>
            <point>0.0103446 -0.049732</point>
            <point>0.0306891 -0.0454448</point>
            <point>0.0499998 -0.0368705</point>
            <point>0.0670808 -0.0244341</point>
            <point>0.0809659 -0.00895876</point>
            <point>0.0913106 0.00895864</point>
            <point>0.0977701 0.0287212</point>
            <point>0.0999998 0.049732</point>
            <point>0.0899999 0.049732</point>
            <point>0.0879932 0.0308222</point>
            <point>0.0821797 0.0130359</point>
            <point>0.0728696 -0.00308987</point>
            <point>0.060373 -0.0170178</point>
            <point>0.0450001 -0.0282106</point>
            <point>0.0276204 -0.0359275</point>
            <point>0.00931019 -0.039786</point>
            <point>-0.00931018 -0.039786</point>
            <point>-0.0276204 -0.0359275</point>
            <point>-0.0450001 -0.0282106</point>
            <point>-0.060373 -0.0170178</point>
            <point>-0.0728696 -0.00308987</point>
            <point>-0.0821797 0.0130359</point>
            <point>-0.0879932 0.0308222</point>
            <point>-0.0899999 0.0497319</point>
            <point>-0.0999998 0.049732</point>
          </polyline>
        </geometry>
        <surface>
          <friction>
            <ode>
              <mu>1</mu>
              <mu2>1</mu2>
              <fdir1>0 0 0</fdir1>
              <slip1>0</slip1>
              <slip2>0</slip2>
            </ode>
            <torsional>
              <coefficient>1</coefficient>
              <patch_radius>0</patch_radius>
              <surface_radius>0</surface_radius>
              <use_patch_radius>1</use_patch_radius>
              <ode>
                <slip>0</slip>
              </ode>
            </torsional>
          </friction>
          <bounce>
            <restitution_coefficient>0</restitution_coefficient>
            <threshold>1e+06</threshold>
          </bounce>
          <contact>
            <collide_without_contact>0</collide_without_contact>
            <collide_without_contact_bitmask>1</collide_without_contact_bitmask>
            <collide_bitmask>1</collide_bitmask>
            <ode>
              <soft_cfm>0</soft_cfm>
              <soft_erp>0.2</soft_erp>
              <kp>1e+13</kp>
              <kd>1</kd>
              <max_vel>0.01</max_vel>
              <min_depth>0</min_depth>
            </ode>
            <bullet>
              <split_impulse>1</split_impulse>
              <split_impulse_penetration_threshold>-0.01</split_impulse_penetration_threshold>
              <soft_cfm>0</soft_cfm>
              <soft_erp>0.2</soft_erp>
              <kp>1e+13</kp>
              <kd>1</kd>
            </bullet>
          </contact>
        </surface>
      </collision>
    </link>
    <link name='link_2_clone_1_clone'>
      <inertial>
        <mass>1</mass>
        <inertia>
          <ixx>0.166667</ixx>
          <ixy>0</ixy>
          <ixz>0</ixz>
          <iyy>0.166667</iyy>
          <iyz>0</iyz>
          <izz>0.166667</izz>
        </inertia>
        <pose frame=''>0 0 0 0 -0 0</pose>
      </inertial>
      <pose frame=''>-0.071663 0.327402 -0.014286 -0.000654 1.5707 -1.57138</pose>
      <gravity>1</gravity>
      <self_collide>0</self_collide>
      <kinematic>0</kinematic>
      <enable_wind>0</enable_wind>
      <visual name='visual'>
        <pose frame=''>0 0 0 0 -0 0</pose>
        <geometry>
          <polyline>
            <height>0.1</height>
            <point>-0.0999998 0.049686</point>
            <point>-0.0977624 0.0286855</point>
            <point>-0.0912994 0.00893357</point>
            <point>-0.080955 -0.00897376</point>
            <point>-0.0670737 -0.0244405</point>
            <point>-0.0499998 -0.0368705</point>
            <point>-0.0306891 -0.0454448</point>
            <point>-0.0103446 -0.049732</point>
            <point>0.0103446 -0.049732</point>
            <point>0.0306891 -0.0454448</point>
            <point>0.0499998 -0.0368705</point>
            <point>0.0670808 -0.0244341</point>
            <point>0.0809659 -0.00895876</point>
            <point>0.0913106 0.00895864</point>
            <point>0.0977701 0.0287212</point>
            <point>0.0999998 0.049732</point>
            <point>0.0899999 0.049732</point>
            <point>0.0879932 0.0308222</point>
            <point>0.0821797 0.0130359</point>
            <point>0.0728696 -0.00308987</point>
            <point>0.060373 -0.0170178</point>
            <point>0.0450001 -0.0282106</point>
            <point>0.0276204 -0.0359275</point>
            <point>0.00931019 -0.039786</point>
            <point>-0.00931018 -0.039786</point>
            <point>-0.0276204 -0.0359275</point>
            <point>-0.0450001 -0.0282106</point>
            <point>-0.060373 -0.0170178</point>
            <point>-0.0728696 -0.00308987</point>
            <point>-0.0821797 0.0130359</point>
            <point>-0.0879932 0.0308222</point>
            <point>-0.0899999 0.0497319</point>
            <point>-0.0999998 0.049732</point>
          </polyline>
        </geometry>
        <material>
          <lighting>1</lighting>
          <script>
            <uri>file://media/materials/scripts/gazebo.material</uri>
            <name>Gazebo/Grey</name>
          </script>
          <shader type='vertex'>
            <normal_map>__default__</normal_map>
          </shader>
          <ambient>1 1 1 1</ambient>
          <diffuse>0.7 0.7 0.7 1</diffuse>
          <specular>0.01 0.01 0.01 1</specular>
          <emissive>0 0 0 1</emissive>
        </material>
        <transparency>0</transparency>
        <cast_shadows>1</cast_shadows>
      </visual>
      <collision name='collision'>
        <laser_retro>0</laser_retro>
        <max_contacts>10</max_contacts>
        <pose frame=''>0 0 0 0 -0 0</pose>
        <geometry>
          <polyline>
            <height>0.1</height>
            <point>-0.0999998 0.049686</point>
            <point>-0.0977624 0.0286855</point>
            <point>-0.0912994 0.00893357</point>
            <point>-0.080955 -0.00897376</point>
            <point>-0.0670737 -0.0244405</point>
            <point>-0.0499998 -0.0368705</point>
            <point>-0.0306891 -0.0454448</point>
            <point>-0.0103446 -0.049732</point>
            <point>0.0103446 -0.049732</point>
            <point>0.0306891 -0.0454448</point>
            <point>0.0499998 -0.0368705</point>
            <point>0.0670808 -0.0244341</point>
            <point>0.0809659 -0.00895876</point>
            <point>0.0913106 0.00895864</point>
            <point>0.0977701 0.0287212</point>
            <point>0.0999998 0.049732</point>
            <point>0.0899999 0.049732</point>
            <point>0.0879932 0.0308222</point>
            <point>0.0821797 0.0130359</point>
            <point>0.0728696 -0.00308987</point>
            <point>0.060373 -0.0170178</point>
            <point>0.0450001 -0.0282106</point>
            <point>0.0276204 -0.0359275</point>
            <point>0.00931019 -0.039786</point>
            <point>-0.00931018 -0.039786</point>
            <point>-0.0276204 -0.0359275</point>
            <point>-0.0450001 -0.0282106</point>
            <point>-0.060373 -0.0170178</point>
            <point>-0.0728696 -0.00308987</point>
            <point>-0.0821797 0.0130359</point>
            <point>-0.0879932 0.0308222</point>
            <point>-0.0899999 0.0497319</point>
            <point>-0.0999998 0.049732</point>
          </polyline>
        </geometry>
        <surface>
          <friction>
            <ode>
              <mu>1</mu>
              <mu2>1</mu2>
              <fdir1>0 0 0</fdir1>
              <slip1>0</slip1>
              <slip2>0</slip2>
            </ode>
            <torsional>
              <coefficient>1</coefficient>
              <patch_radius>0</patch_radius>
              <surface_radius>0</surface_radius>
              <use_patch_radius>1</use_patch_radius>
              <ode>
                <slip>0</slip>
              </ode>
            </torsional>
          </friction>
          <bounce>
            <restitution_coefficient>0</restitution_coefficient>
            <threshold>1e+06</threshold>
          </bounce>
          <contact>
            <collide_without_contact>0</collide_without_contact>
            <collide_without_contact_bitmask>1</collide_without_contact_bitmask>
            <collide_bitmask>1</collide_bitmask>
            <ode>
              <soft_cfm>0</soft_cfm>
              <soft_erp>0.2</soft_erp>
              <kp>1e+13</kp>
              <kd>1</kd>
              <max_vel>0.01</max_vel>
              <min_depth>0</min_depth>
            </ode>
            <bullet>
              <split_impulse>1</split_impulse>
              <split_impulse_penetration_threshold>-0.01</split_impulse_penetration_threshold>
              <soft_cfm>0</soft_cfm>
              <soft_erp>0.2</soft_erp>
              <kp>1e+13</kp>
              <kd>1</kd>
            </bullet>
          </contact>
        </surface>
      </collision>
    </link>
    <link name='link_2_clone_1_clone_0'>
      <inertial>
        <mass>1</mass>
        <inertia>
          <ixx>0.166667</ixx>
          <ixy>0</ixy>
          <ixz>0</ixz>
          <iyy>0.166667</iyy>
          <iyz>0</iyz>
          <izz>0.166667</izz>
        </inertia>
        <pose frame=''>0 0 0 0 -0 0</pose>
      </inertial>
      <pose frame=''>0.128337 0.207402 -0.014286 -0.000654 1.5707 -1.57138</pose>
      <gravity>1</gravity>
      <self_collide>0</self_collide>
      <kinematic>0</kinematic>
      <enable_wind>0</enable_wind>
      <visual name='visual'>
        <pose frame=''>0 0 0 0 -0 0</pose>
        <geometry>
          <polyline>
            <height>0.1</height>
            <point>-0.0999998 0.049686</point>
            <point>-0.0977624 0.0286855</point>
            <point>-0.0912994 0.00893357</point>
            <point>-0.080955 -0.00897376</point>
            <point>-0.0670737 -0.0244405</point>
            <point>-0.0499998 -0.0368705</point>
            <point>-0.0306891 -0.0454448</point>
            <point>-0.0103446 -0.049732</point>
            <point>0.0103446 -0.049732</point>
            <point>0.0306891 -0.0454448</point>
            <point>0.0499998 -0.0368705</point>
            <point>0.0670808 -0.0244341</point>
            <point>0.0809659 -0.00895876</point>
            <point>0.0913106 0.00895864</point>
            <point>0.0977701 0.0287212</point>
            <point>0.0999998 0.049732</point>
            <point>0.0899999 0.049732</point>
            <point>0.0879932 0.0308222</point>
            <point>0.0821797 0.0130359</point>
            <point>0.0728696 -0.00308987</point>
            <point>0.060373 -0.0170178</point>
            <point>0.0450001 -0.0282106</point>
            <point>0.0276204 -0.0359275</point>
            <point>0.00931019 -0.039786</point>
            <point>-0.00931018 -0.039786</point>
            <point>-0.0276204 -0.0359275</point>
            <point>-0.0450001 -0.0282106</point>
            <point>-0.060373 -0.0170178</point>
            <point>-0.0728696 -0.00308987</point>
            <point>-0.0821797 0.0130359</point>
            <point>-0.0879932 0.0308222</point>
            <point>-0.0899999 0.0497319</point>
            <point>-0.0999998 0.049732</point>
          </polyline>
        </geometry>
        <material>
          <lighting>1</lighting>
          <script>
            <uri>file://media/materials/scripts/gazebo.material</uri>
            <name>Gazebo/Grey</name>
          </script>
          <shader type='vertex'>
            <normal_map>__default__</normal_map>
          </shader>
          <ambient>1 1 1 1</ambient>
          <diffuse>0.7 0.7 0.7 1</diffuse>
          <specular>0.01 0.01 0.01 1</specular>
          <emissive>0 0 0 1</emissive>
        </material>
        <transparency>0</transparency>
        <cast_shadows>1</cast_shadows>
      </visual>
      <collision name='collision'>
        <laser_retro>0</laser_retro>
        <max_contacts>10</max_contacts>
        <pose frame=''>0 0 0 0 -0 0</pose>
        <geometry>
          <polyline>
            <height>0.1</height>
            <point>-0.0999998 0.049686</point>
            <point>-0.0977624 0.0286855</point>
            <point>-0.0912994 0.00893357</point>
            <point>-0.080955 -0.00897376</point>
            <point>-0.0670737 -0.0244405</point>
            <point>-0.0499998 -0.0368705</point>
            <point>-0.0306891 -0.0454448</point>
            <point>-0.0103446 -0.049732</point>
            <point>0.0103446 -0.049732</point>
            <point>0.0306891 -0.0454448</point>
            <point>0.0499998 -0.0368705</point>
            <point>0.0670808 -0.0244341</point>
            <point>0.0809659 -0.00895876</point>
            <point>0.0913106 0.00895864</point>
            <point>0.0977701 0.0287212</point>
            <point>0.0999998 0.049732</point>
            <point>0.0899999 0.049732</point>
            <point>0.0879932 0.0308222</point>
            <point>0.0821797 0.0130359</point>
            <point>0.0728696 -0.00308987</point>
            <point>0.060373 -0.0170178</point>
            <point>0.0450001 -0.0282106</point>
            <point>0.0276204 -0.0359275</point>
            <point>0.00931019 -0.039786</point>
            <point>-0.00931018 -0.039786</point>
            <point>-0.0276204 -0.0359275</point>
            <point>-0.0450001 -0.0282106</point>
            <point>-0.060373 -0.0170178</point>
            <point>-0.0728696 -0.00308987</point>
            <point>-0.0821797 0.0130359</point>
            <point>-0.0879932 0.0308222</point>
            <point>-0.0899999 0.0497319</point>
            <point>-0.0999998 0.049732</point>
          </polyline>
        </geometry>
        <surface>
          <friction>
            <ode>
              <mu>1</mu>
              <mu2>1</mu2>
              <fdir1>0 0 0</fdir1>
              <slip1>0</slip1>
              <slip2>0</slip2>
            </ode>
            <torsional>
              <coefficient>1</coefficient>
              <patch_radius>0</patch_radius>
              <surface_radius>0</surface_radius>
              <use_patch_radius>1</use_patch_radius>
              <ode>
                <slip>0</slip>
              </ode>
            </torsional>
          </friction>
          <bounce>
            <restitution_coefficient>0</restitution_coefficient>
            <threshold>1e+06</threshold>
          </bounce>
          <contact>
            <collide_without_contact>0</collide_without_contact>
            <collide_without_contact_bitmask>1</collide_without_contact_bitmask>
            <collide_bitmask>1</collide_bitmask>
            <ode>
              <soft_cfm>0</soft_cfm>
              <soft_erp>0.2</soft_erp>
              <kp>1e+13</kp>
              <kd>1</kd>
              <max_vel>0.01</max_vel>
              <min_depth>0</min_depth>
            </ode>
            <bullet>
              <split_impulse>1</split_impulse>
              <split_impulse_penetration_threshold>-0.01</split_impulse_penetration_threshold>
              <soft_cfm>0</soft_cfm>
              <soft_erp>0.2</soft_erp>
              <kp>1e+13</kp>
              <kd>1</kd>
            </bullet>
          </contact>
        </surface>
      </collision>
    </link>
    <joint name='link_0_JOINT_1' type='revolute'>
      <parent>link_0</parent>
      <child>link_2</child>
      <pose frame=''>-0.1 0.05 0 0 -0 0</pose>
      <axis>
        <xyz>0 0 1</xyz>
        <use_parent_model_frame>0</use_parent_model_frame>
        <limit>
          <lower>-1.79769e+308</lower>
          <upper>1.79769e+308</upper>
          <effort>-1</effort>
          <velocity>-1</velocity>
        </limit>
        <dynamics>
          <spring_reference>0</spring_reference>
          <spring_stiffness>0</spring_stiffness>
          <damping>0</damping>
          <friction>0</friction>
        </dynamics>
      </axis>
      <physics>
        <ode>
          <limit>
            <cfm>0</cfm>
            <erp>0.2</erp>
          </limit>
          <suspension>
            <cfm>0</cfm>
            <erp>0.2</erp>
          </suspension>
        </ode>
      </physics>
    </joint>
    <joint name='link_0_JOINT_2' type='revolute'>
      <parent>link_0</parent>
      <child>link_2_clone</child>
      <pose frame=''>-0.1 0.05 0 0 -0 0</pose>
      <axis>
        <xyz>0 0 1</xyz>
        <use_parent_model_frame>0</use_parent_model_frame>
        <limit>
          <lower>-1.79769e+308</lower>
          <upper>1.79769e+308</upper>
          <effort>-1</effort>
          <velocity>-1</velocity>
        </limit>
        <dynamics>
          <spring_reference>0</spring_reference>
          <spring_stiffness>0</spring_stiffness>
          <damping>0</damping>
          <friction>0</friction>
        </dynamics>
      </axis>
      <physics>
        <ode>
          <limit>
            <cfm>0</cfm>
            <erp>0.2</erp>
          </limit>
          <suspension>
            <cfm>0</cfm>
            <erp>0.2</erp>
          </suspension>
        </ode>
      </physics>
    </joint>
    <joint name='link_0_JOINT_3' type='revolute'>
      <parent>link_0</parent>
      <child>link_2_clone_0</child>
      <pose frame=''>-0.1 0.05 0 0 -0 0</pose>
      <axis>
        <xyz>0 0 1</xyz>
        <use_parent_model_frame>0</use_parent_model_frame>
        <limit>
          <lower>-1.79769e+308</lower>
          <upper>1.79769e+308</upper>
          <effort>-1</effort>
          <velocity>-1</velocity>
        </limit>
        <dynamics>
          <spring_reference>0</spring_reference>
          <spring_stiffness>0</spring_stiffness>
          <damping>0</damping>
          <friction>0</friction>
        </dynamics>
      </axis>
      <physics>
        <ode>
          <limit>
            <cfm>0</cfm>
            <erp>0.2</erp>
          </limit>
          <suspension>
            <cfm>0</cfm>
            <erp>0.2</erp>
          </suspension>
        </ode>
      </physics>
    </joint>
    <joint name='link_0_JOINT_4' type='revolute'>
      <parent>link_0</parent>
      <child>link_2_clone_1</child>
      <pose frame=''>-0.1 0.05 0.1 0 -0 0</pose>
      <axis>
        <xyz>0 0 1</xyz>
        <use_parent_model_frame>0</use_parent_model_frame>
        <limit>
          <lower>-1.79769e+308</lower>
          <upper>1.79769e+308</upper>
          <effort>-1</effort>
          <velocity>-1</velocity>
        </limit>
        <dynamics>
          <spring_reference>0</spring_reference>
          <spring_stiffness>0</spring_stiffness>
          <damping>0</damping>
          <friction>0</friction>
        </dynamics>
      </axis>
      <physics>
        <ode>
          <limit>
            <cfm>0</cfm>
            <erp>0.2</erp>
          </limit>
          <suspension>
            <cfm>0</cfm>
            <erp>0.2</erp>
          </suspension>
        </ode>
      </physics>
    </joint>
    <joint name='link_0_JOINT_5' type='revolute'>
      <parent>link_0</parent>
      <child>link_2_clone_1_clone</child>
      <pose frame=''>-0.1 0.05 0.1 0 -0 0</pose>
      <axis>
        <xyz>0 0 1</xyz>
        <use_parent_model_frame>0</use_parent_model_frame>
        <limit>
          <lower>-1.79769e+308</lower>
          <upper>1.79769e+308</upper>
          <effort>-1</effort>
          <velocity>-1</velocity>
        </limit>
        <dynamics>
          <spring_reference>0</spring_reference>
          <spring_stiffness>0</spring_stiffness>
          <damping>0</damping>
          <friction>0</friction>
        </dynamics>
      </axis>
      <physics>
        <ode>
          <limit>
            <cfm>0</cfm>
            <erp>0.2</erp>
          </limit>
          <suspension>
            <cfm>0</cfm>
            <erp>0.2</erp>
          </suspension>
        </ode>
      </physics>
    </joint>
    <joint name='link_0_JOINT_6' type='revolute'>
      <parent>link_0</parent>
      <child>link_2_clone_1_clone_0</child>
      <pose frame=''>-0.1 0.05 0.1 0 -0 0</pose>
      <axis>
        <xyz>0 0 1</xyz>
        <use_parent_model_frame>0</use_parent_model_frame>
        <limit>
          <lower>-1.79769e+308</lower>
          <upper>1.79769e+308</upper>
          <effort>-1</effort>
          <velocity>-1</velocity>
        </limit>
        <dynamics>
          <spring_reference>0</spring_reference>
          <spring_stiffness>0</spring_stiffness>
          <damping>0</damping>
          <friction>0</friction>
        </dynamics>
      </axis>
      <physics>
        <ode>
          <limit>
            <cfm>0</cfm>
            <erp>0.2</erp>
          </limit>
          <suspension>
            <cfm>0</cfm>
            <erp>0.2</erp>
          </suspension>
        </ode>
      </physics>
    </joint>
    <static>0</static>
    <allow_auto_disable>1</allow_auto_disable>
  </model>
</sdf>
